Workbook
Name MY_FUNCTION1: LAMBDA((('Dataset Indeks Harga Konsumen'!$H$5-'Dataset Indeks Harga Konsumen'!$I$5)/'Dataset Indeks Harga Konsumen'!$I$5)*100)

Sheet Instruction
C2: Instruction
C3: Day 2 | D3: Lakukan cleansing data di tab sheet "Dataset Index Harga Konsumen" kemudian lengkapi kolom berwarna kuning dengan acuan referensi yang ada di tab sheet "Reference"
C4: Day 3 | D4: Jawab pertanyaan Business Question A yang ada di tab sheet "Business Question dengan menggunakan Pivot Table, tab sheet Pivot Table telah disediakan
C5: Day 5 | D5: Buatlah Visualisasi Data dengan Looker Studio berdasarkan pertanyaan Business Question B yang ada di sheet "Business Question", gunakan chart yang sesuai menurut penilaian kamu
C7: Glossary
C8: Istilah | D8: Definisi
C9: IHK - Indeks Harga KOnsumen | D9: Indeks yang mengukur rata-rata perubahan harga dari sekelompok barang dan jasa yang dikonsumsi oleh rumah tangga dalam suatu periode waktu tertentu.
C10: Inflasi | D10: Kenaikan harga barang dan jasa secara umum dan terus-menerus dalam suatu periode waktu tertentu.
C11: Deflasi | D11: Penurunan harga barang dan jasa secara umum dan terus-menerus dalam suatu periode waktu tertentu.
C12: M-t-M | D12: Month-to-Month, yang berarti perbandingan atau perubahan dari bulan ke bulan.
C13: Akselerasi | D13: Proses atau keadaan meningkatnya kecepatan suatu perubahan, bisa berarti percepatan dalam laju pertumbuhan, perkembangan, atau peningkatan sesuatu.
C14: Perubahan Poin Absolut | D14: Selisih langsung (dalam satuan poin) antara dua nilai indeks atau persentase
C15: Fluktuatif | D15: Keadaan yang berubah-ubah secara tidak tetap atau tidak stabil dalam suatu periode waktu.
C16: Data Agregat | D16: Data yang diperoleh dengan cara menggabungkan atau menjumlahkan data dari beberapa individu, kelompok, atau kategori menjadi satu kesatuan yang lebih besar.
C17: Peta Panas | D17: Visualisasi data dalam bentuk warna yang menunjukkan tingkat intensitas, frekuensi, atau nilai dari suatu variabel di suatu area atau tabel.
C18: Kontributor Poin | D18: Unsur atau komponen yang memberikan sumbangan (kontribusi) terhadap perubahan total suatu nilai dalam satuan poin.
C19: Control Interaktif | D19: Komponen atau elemen pada dashboard Looker Studio yang memungkinkan pengguna berinteraksi langsung dengan data — misalnya memfilter, memilih rentang waktu, atau menampilkan subset data tertentu secara dinamis.

Sheet Reference
A1: Ref 1. Data Provinsi dan Kota/Kabupaten | D1: Ref 2. Kelompok Kategori | H1: Ref 3a. Laju Inflasi | K1: Ref 4a. Perubahan Harga Relatif
A2: Kota/Kabupaten | B2: Provinsi | D2: Kelompok Kategori | E2: Kategori ID | F2: Kategori | H2: Inflasi | I2: Kriteria | K2: Output | L2: Status | M2: Definisi
A3: Kab Aceh Tengah | B3: Aceh | D3: Makanan dan Pakaian | E3: SUB-1124 | F3: Makanan | H3: > 0.50% | I3: Inflasi Tinggi | K3: Inflasi M-t-M (Persentase) ≥ 0.5% DAN Perubahan Poin IHK (Absolut) ≥ 2.0 | L3: Akselerasi Kuat | M3: Inflasi Tinggi dengan Dampak yang Berat
A4: Meulaboh | B4: Aceh | D4: Makanan dan Pakaian | E4: SUB-1224 | F4: Minuman | H4: > 0.00% dan ≤ 0.50% | I4: Inflasi Normal | K4: Inflasi M-t-M (Persentase) ≥ 0.5% | L4: Akselerasi Persentase | M4: Sinyal Awal terjadi Inflasi yang Signifikan
A5: Kab Aceh Tamiang | B5: Aceh | D5: Makanan dan Pakaian | E5: SUB-1324 | F5: Pakaian | H5: 0.00% | I5: Stabil | K5: Perubahan Poin IHK (Absolut) ≥ 2.0 | L5: Akselerasi Poin Absolut | M5: Harga Barang Sudah Mahal
A6: Kota Banda Aceh | B6: Aceh | D6: Makanan dan Pakaian | E6: SUB-1424 | F6: Alas Kaki | H6: < 0.00% | I6: Deflasi | K6: Selain ketiga hal di atas | L6: Perubahan Normal | M6: Normal
A7: Kota Lhokseumawe | B7: Aceh | D7: Rumah Tangga | E7: SUB-2124 | F7: Sewa Rumah
A8: Kab Labuhanbatu | B8: Sumatera Utara | D8: Rumah Tangga | E8: SUB-2224 | F8: Listrik | H8: Ref 3b. Rumus Laju Inflasi | K8: Ref 4b. Rumus Perubahan Poin IHK
A9: Kab Karo | B9: Sumatera Utara | D9: Rumah Tangga | E9: SUB-2324 | F9: Furniture | H9: ((IHK periode ini – IHK periode sebelumnya) / IHK periode sebelumnya) x 100% | K9: IHK periode ini - IHK periode sebelumnya
A10: Kab Deli Serdang | B10: Sumatera Utara | D10: Pendidikan dan Kesehatan | E10: SUB-3124 | F10: Pendidikan
A11: Kota Sibolga | B11: Sumatera Utara | D11: Pendidikan dan Kesehatan | E11: SUB-3224 | F11: Produk Kesehatan
A12: Kota Pematangsiantar | B12: Sumatera Utara | D12: Rekreasi dan Kendaraan | E12: SUB-4124 | F12: Rekreasi
A13: Kota Medan | B13: Sumatera Utara | D13: Rekreasi dan Kendaraan | E13: SUB-4224 | F13: Kendaraan
A14: Kota Padangsidimpuan | B14: Sumatera Utara
A15: Kota Gunungsitoli | B15: Sumatera Utara
A16: Kab Dharmasraya | B16: Sumatera Barat
A17: Kab Pasaman Barat | B17: Sumatera Barat
A18: Kota Padang | B18: Sumatera Barat
A19: Kota Bukittinggi | B19: Sumatera Barat
A20: Tembilahan | B20: Riau
A21: Kab Kampar | B21: Riau
A22: Kota Pekanbaru | B22: Riau
A23: Kota Dumai | B23: Riau
A24: Kab Kerinci | B24: Jambi
A25: Muara Bungo | B25: Jambi
... A152: Kab Jayawijaya | B152: Papua

Sheet Dataset Indeks Harga Konsumen
A1: Data Badan Pusat Statistik - Indeks Harga Konsumen per Kota/Kabupaten Periode Januari - Maret 2024
B3: Cleansing data | C3: Acuan Ref. 1 | F3: Acuan Ref. 2 | J3: Acuan Ref. 3b | K3: Acuan Ref. 3a | L3: Acuan Ref. 4b | M3: Acuan Ref. 4a
A4: Kota/Kabupaten | B4: Proper | C4: Provinsi | D4: Data ID | E4: Bulan Pencatatan | F4: Kelompok Kategori | G4: Kategori | H4: Index Harga Konsumen (IHK) | I4: Index Harga Konsumen (IHK) Bulan Lalu | J4: Laju Inflasi M-t-M | K4: Kriteria Inflasi | L4: Perubahan Poin IHK | M4: Status Perubahan Harga Relatif
A5: KAB LABUHANBATU | B5: =PROPER(A5) -> Kab Labuhanbatu | C5: {=XLOOKUP(B5,Reference!$A$2:$A$152,Reference!$B$2:$B$152)} -> Sumatera Utara | D5: BPS-00622224 | E5: 45323 | F5: {=XLOOKUP(G5,Reference!$F:$F,Reference!$D:$D,"null")} -> Rumah Tangga | G5: Listrik | H5: 104.73 | I5: 104.73 | J5: =((H5-I5)/I5)*100 -> 0 | K5: =ifs(J5=0,"Stabil",J5<0,"Deflasi",J5>0.51,"Inflasi Tinggi",TRUE,"Inflasi Normal") -> Stabil | L5: =H5-I5 -> 0 | M5: =IFS(AND(J5>=0.5,L5>=2),"Akselerasi Kuat",J5>=0.5,"Akselerasi Persentase",L5>=2,"Akselerasi Poin Absolut",TRUE,"Perubahan Normal") -> Perubahan Normal
A6: KOTA BOGOR | B6: =PROPER(A6) -> Kota Bogor | C6: {=XLOOKUP(B6,Reference!$A$2:$A$152,Reference!$B$2:$B$152)} -> Jawa Barat | D6: BPS-04632224 | E6: 45352 | F6: {=XLOOKUP(G6,Reference!$F:$F,Reference!$D:$D,"null")} -> Rumah Tangga | G6: Listrik | H6: 104.08 | I6: 104.08 | J6: =((H6-I6)/I6)*100 -> 0 | K6: =ifs(J6=0,"Stabil",J6<0,"Deflasi",J6>0.51,"Inflasi Tinggi",TRUE,"Inflasi Normal") -> Stabil | L6: =H6-I6 -> 0 | M6: =IFS(AND(J6>=0.5,L6>=2),"Akselerasi Kuat",J6>=0.5,"Akselerasi Persentase",L6>=2,"Akselerasi Poin Absolut",TRUE,"Perubahan Normal") -> Perubahan Normal
A7: KOTA BEKASI | B7: =PROPER(A7) -> Kota Bekasi | C7: {=XLOOKUP(B7,Reference!$A$2:$A$152,Reference!$B$2:$B$152)} -> Jawa Barat | D7: BPS-05034124 | E7: 45352 | F7: {=XLOOKUP(G7,Reference!$F:$F,Reference!$D:$D,"null")} -> Rekreasi dan Kendaraan | G7: Rekreasi | H7: 110.05 | I7: 110.05 | J7: =((H7-I7)/I7)*100 -> 0 | K7: =ifs(J7=0,"Stabil",J7<0,"Deflasi",J7>0.51,"Inflasi Tinggi",TRUE,"Inflasi Normal") -> Stabil | L7: =H7-I7 -> 0 | M7: =IFS(AND(J7>=0.5,L7>=2),"Akselerasi Kuat",J7>=0.5,"Akselerasi Persentase",L7>=2,"Akselerasi Poin Absolut",TRUE,"Perubahan Normal") -> Perubahan Normal
A8: SINTANG | B8: =PROPER(A8) -> Sintang | C8: {=XLOOKUP(B8,Reference!$A$2:$A$152,Reference!$B$2:$B$152)} -> Kalimantan Barat | D8: BPS-09332324 | E8: 45352 | F8: {=XLOOKUP(G8,Reference!$F:$F,Reference!$D:$D,"null")} -> Rumah Tangga | G8: Furniture | H8: 107.64 | I8: 107.64 | J8: =((H8-I8)/I8)*100 -> 0 | K8: =ifs(J8=0,"Stabil",J8<0,"Deflasi",J8>0.51,"Inflasi Tinggi",TRUE,"Inflasi Normal") -> Stabil | L8: =H8-I8 -> 0 | M8: =IFS(AND(J8>=0.5,L8>=2),"Akselerasi Kuat",J8>=0.5,"Akselerasi Persentase",L8>=2,"Akselerasi Poin Absolut",TRUE,"Perubahan Normal") -> Perubahan Normal
A9: KOTA LUBUK LINGGAU | B9: =PROPER(A9) -> Kota Lubuk Linggau | C9: {=XLOOKUP(B9,Reference!$A$2:$A$152,Reference!$B$2:$B$152)} -> Sumatera Selatan | D9: BPS-02832324 | E9: 45352 | F9: {=XLOOKUP(G9,Reference!$F:$F,Reference!$D:$D,"null")} -> Rumah Tangga | G9: Furniture | H9: 101.04 | I9: 101.36 | J9: =((H9-I9)/I9)*100 -> -0.31570639 | K9: =ifs(J9=0,"Stabil",J9<0,"Deflasi",J9>0.51,"Inflasi Tinggi",TRUE,"Inflasi Normal") -> Deflasi | L9: =H9-I9 -> -0.32 | M9: =IFS(AND(J9>=0.5,L9>=2),"Akselerasi Kuat",J9>=0.5,"Akselerasi Persentase",L9>=2,"Akselerasi Poin Absolut",TRUE,"Perubahan Normal") -> Perubahan Normal
A10: KOTA KEDIRI | B10: =PROPER(A10) -> Kota Kediri | C10: {=XLOOKUP(B10,Reference!$A$2:$A$152,Reference!$B$2:$B$152)} -> Jawa Timur | D10: BPS-07031224 | E10: 45352 | F10: {=XLOOKUP(G10,Reference!$F:$F,Reference!$D:$D,"null")} -> Makanan dan Pakaian | G10: Minuman | H10: 103.13 | I10: 103.13 | J10: =((H10-I10)/I10)*100 -> 0 | K10: =ifs(J10=0,"Stabil",J10<0,"Deflasi",J10>0.51,"Inflasi Tinggi",TRUE,"Inflasi Normal") -> Stabil | L10: =H10-I10 -> 0 | M10: =IFS(AND(J10>=0.5,L10>=2),"Akselerasi Kuat",J10>=0.5,"Akselerasi Persentase",L10>=2,"Akselerasi Poin Absolut",TRUE,"Perubahan Normal") -> Perubahan Normal
A11: KOTA PADANG | B11: =PROPER(A11) -> Kota Padang | C11: {=XLOOKUP(B11,Reference!$A$2:$A$152,Reference!$B$2:$B$152)} -> Sumatera Barat | D11: BPS-01623124 | E11: 45323 | F11: {=XLOOKUP(G11,Reference!$F:$F,Reference!$D:$D,"null")} -> Pendidikan dan Kesehatan | G11: Pendidikan | H11: 103.02 | I11: 103.02 | J11: =((H11-I11)/I11)*100 -> 0 | K11: =ifs(J11=0,"Stabil",J11<0,"Deflasi",J11>0.51,"Inflasi Tinggi",TRUE,"Inflasi Normal") -> Stabil | L11: =H11-I11 -> 0 | M11: =IFS(AND(J11>=0.5,L11>=2),"Akselerasi Kuat",J11>=0.5,"Akselerasi Persentase",L11>=2,"Akselerasi Poin Absolut",TRUE,"Perubahan Normal") -> Perubahan Normal
A12: KAB SUKAMARA | B12: =PROPER(A12) -> Kab Sukamara | C12: {=XLOOKUP(B12,Reference!$A$2:$A$152,Reference!$B$2:$B$152)} -> Kalimantan Tengah | D12: BPS-09923224 | E12: 45323 | F12: {=XLOOKUP(G12,Reference!$F:$F,Reference!$D:$D,"null")} -> Pendidikan dan Kesehatan | G12: Produk Kesehatan | H12: 105.59 | I12: 103.91 | J12: =((H12-I12)/I12)*100 -> 1.6167838 | K12: =ifs(J12=0,"Stabil",J12<0,"Deflasi",J12>0.51,"Inflasi Tinggi",TRUE,"Inflasi Normal") -> Inflasi Tinggi | L12: =H12-I12 -> 1.68 | M12: =IFS(AND(J12>=0.5,L12>=2),"Akselerasi Kuat",J12>=0.5,"Akselerasi Persentase",L12>=2,"Akselerasi Poin Absolut",TRUE,"Perubahan Normal") -> Akselerasi Persentase
A13: KAB KAMPAR | B13: =PROPER(A13) -> Kab Kampar | C13: {=XLOOKUP(B13,Reference!$A$2:$A$152,Reference!$B$2:$B$152)} -> Riau | D13: BPS-01934224 | E13: 45352 | F13: {=XLOOKUP(G13,Reference!$F:$F,Reference!$D:$D,"null")} -> Rekreasi dan Kendaraan | G13: Kendaraan | H13: 99.59 | I13: 99.59 | J13: =((H13-I13)/I13)*100 -> 0 | K13: =ifs(J13=0,"Stabil",J13<0,"Deflasi",J13>0.51,"Inflasi Tinggi",TRUE,"Inflasi Normal") -> Stabil | L13: =H13-I13 -> 0 | M13: =IFS(AND(J13>=0.5,L13>=2),"Akselerasi Kuat",J13>=0.5,"Akselerasi Persentase",L13>=2,"Akselerasi Poin Absolut",TRUE,"Perubahan Normal") -> Perubahan Normal
A14: KAB JAYAWIJAYA | B14: =PROPER(A14) -> Kab Jayawijaya | C14: {=XLOOKUP(B14,Reference!$A$2:$A$152,Reference!$B$2:$B$152)} -> Papua | D14: BPS-15033124 | E14: 45352 | F14: {=XLOOKUP(G14,Reference!$F:$F,Reference!$D:$D,"null")} -> Pendidikan dan Kesehatan | G14: Pendidikan | H14: 100 | I14: 100 | J14: =((H14-I14)/I14)*100 -> 0 | K14: =ifs(J14=0,"Stabil",J14<0,"Deflasi",J14>0.51,"Inflasi Tinggi",TRUE,"Inflasi Normal") -> Stabil | L14: =H14-I14 -> 0 | M14: =IFS(AND(J14>=0.5,L14>=2),"Akselerasi Kuat",J14>=0.5,"Akselerasi Persentase",L14>=2,"Akselerasi Poin Absolut",TRUE,"Perubahan Normal") -> Perubahan Normal
A15: KOTA JAYAPURA | B15: =PROPER(A15) -> Kota Jayapura | C15: {=XLOOKUP(B15,Reference!$A$2:$A$152,Reference!$B$2:$B$152)} -> Papua | D15: BPS-14634224 | E15: 45352 | F15: {=XLOOKUP(G15,Reference!$F:$F,Reference!$D:$D,"null")} -> Rekreasi dan Kendaraan | G15: Kendaraan | H15: 104.53 | I15: 104.53 | J15: =((H15-I15)/I15)*100 -> 0 | K15: =ifs(J15=0,"Stabil",J15<0,"Deflasi",J15>0.51,"Inflasi Tinggi",TRUE,"Inflasi Normal") -> Stabil | L15: =H15-I15 -> 0 | M15: =IFS(AND(J15>=0.5,L15>=2),"Akselerasi Kuat",J15>=0.5,"Akselerasi Persentase",L15>=2,"Akselerasi Poin Absolut",TRUE,"Perubahan Normal") -> Perubahan Normal
A16: SINGARAJA | B16: =PROPER(A16) -> Singaraja | C16: {=XLOOKUP(B16,Reference!$A$2:$A$152,Reference!$B$2:$B$152)} -> Bali | D16: BPS-08232224 | E16: 45352 | F16: {=XLOOKUP(G16,Reference!$F:$F,Reference!$D:$D,"null")} -> Rumah Tangga | G16: Listrik | H16: 104.28 | I16: 104.28 | J16: =((H16-I16)/I16)*100 -> 0 | K16: =ifs(J16=0,"Stabil",J16<0,"Deflasi",J16>0.51,"Inflasi Tinggi",TRUE,"Inflasi Normal") -> Stabil | L16: =H16-I16 -> 0 | M16: =IFS(AND(J16>=0.5,L16>=2),"Akselerasi Kuat",J16>=0.5,"Akselerasi Persentase",L16>=2,"Akselerasi Poin Absolut",TRUE,"Perubahan Normal") -> Perubahan Normal
... A2323: KAB KAMPAR | B2323: =PROPER(A2323) -> Kab Kampar | C2323: {=XLOOKUP(B2323,Reference!$A$2:$A$152,Reference!$B$2:$B$152)} -> Riau | D2323: BPS-01931124 | E2323: 45352 | F2323: {=XLOOKUP(G2323,Reference!$F:$F,Reference!$D:$D,"null")} -> Makanan dan Pakaian | G2323: Makanan | H2323: 112.32 | I2323: 110.4 | J2323: =((H2323-I2323)/I2323)*100 -> 1.7391304 | K2323: =ifs(J2323=0,"Stabil",J2323<0,"Deflasi",J2323>0.51,"Inflasi Tinggi",TRUE,"Inflasi Normal") -> Inflasi Tinggi | L2323: =H2323-I2323 -> 1.92 | M2323: =IFS(AND(J2323>=0.5,L2323>=2),"Akselerasi Kuat",J2323>=0.5,"Akselerasi Persentase",L2323>=2,"Akselerasi Poin Absolut",TRUE,"Perubahan Normal") -> Akselerasi Persentase
A2324: KOTA MEDAN | B2324: =PROPER(A2324) -> Kota Medan | C2324: {=xlookup(B2324,Reference!$A$2:$A$152,Reference!$B$2:$B$152)} -> Sumatera Utara | D2324: BPS-01131424 | E2324: 45352 | F2324: {=XLOOKUP(G2324,Reference!$F:$F,Reference!$D:$D,"null")} -> Makanan dan Pakaian | G2324: Alas Kaki | H2324: 101.55 | I2324: 101.55 | J2324: =((H2324-I2324)/I2324)*100 -> 0 | K2324: =ifs(J2324=0,"Stabil",J2324<0,"Deflasi",J2324>0.51,"Inflasi Tinggi",TRUE,"Inflasi Normal") -> Stabil | L2324: =H2324-I2324 -> 0 | M2324: =IFS(AND(J2324>=0.5,L2324>=2),"Akselerasi Kuat",J2324>=0.5,"Akselerasi Persentase",L2324>=2,"Akselerasi Poin Absolut",TRUE,"Perubahan Normal") -> Perubahan Normal
A2325: KAB MESUJI | B2325: =PROPER(A2325) -> Kab Mesuji | C2325: {=xlookup(B2325,Reference!$A$2:$A$152,Reference!$B$2:$B$152)} -> Lampung | D2325: BPS-03224124 | E2325: 45323 | F2325: {=XLOOKUP(G2325,Reference!$F:$F,Reference!$D:$D,"null")} -> Rekreasi dan Kendaraan | G2325: Rekreasi | H2325: 106.99 | I2325: 106.99 | J2325: =((H2325-I2325)/I2325)*100 -> 0 | K2325: =ifs(J2325=0,"Stabil",J2325<0,"Deflasi",J2325>0.51,"Inflasi Tinggi",TRUE,"Inflasi Normal") -> Stabil | L2325: =H2325-I2325 -> 0 | M2325: =IFS(AND(J2325>=0.5,L2325>=2),"Akselerasi Kuat",J2325>=0.5,"Akselerasi Persentase",L2325>=2,"Akselerasi Poin Absolut",TRUE,"Perubahan Normal") -> Perubahan Normal
A2326: KOTA TASIKMALAYA | B2326: =PROPER(A2326) -> Kota Tasikmalaya | C2326: {=xlookup(B2326,Reference!$A$2:$A$152,Reference!$B$2:$B$152)} -> Jawa Barat | D2326: BPS-05224124 | E2326: 45323 | F2326: {=XLOOKUP(G2326,Reference!$F:$F,Reference!$D:$D,"null")} -> Rekreasi dan Kendaraan | G2326: Rekreasi | H2326: 103 | I2326: 102.95 | J2326: =((H2326-I2326)/I2326)*100 -> 0.048567266 | K2326: =ifs(J2326=0,"Stabil",J2326<0,"Deflasi",J2326>0.51,"Inflasi Tinggi",TRUE,"Inflasi Normal") -> Inflasi Normal | L2326: =H2326-I2326 -> 0.05 | M2326: =IFS(AND(J2326>=0.5,L2326>=2),"Akselerasi Kuat",J2326>=0.5,"Akselerasi Persentase",L2326>=2,"Akselerasi Poin Absolut",TRUE,"Perubahan Normal") -> Perubahan Normal
A2327: KOTA KUPANG | B2327: =PROPER(A2327) -> Kota Kupang | C2327: {=xlookup(B2327,Reference!$A$2:$A$152,Reference!$B$2:$B$152)} -> Nusa Tenggara Timur (NTT) | D2327: BPS-09133224 | E2327: 45352 | F2327: {=XLOOKUP(G2327,Reference!$F:$F,Reference!$D:$D,"null")} -> Pendidikan dan Kesehatan | G2327: Produk Kesehatan | H2327: 103.07 | I2327: 103.14 | J2327: =((H2327-I2327)/I2327)*100 -> -0.067868916 | K2327: =ifs(J2327=0,"Stabil",J2327<0,"Deflasi",J2327>0.51,"Inflasi Tinggi",TRUE,"Inflasi Normal") -> Deflasi | L2327: =H2327-I2327 -> -0.07 | M2327: =IFS(AND(J2327>=0.5,L2327>=2),"Akselerasi Kuat",J2327>=0.5,"Akselerasi Persentase",L2327>=2,"Akselerasi Poin Absolut",TRUE,"Perubahan Normal") -> Perubahan Normal
A2328: KAB NGADA | B2328: =PROPER(A2328) -> Kab Ngada | C2328: {=xlookup(B2328,Reference!$A$2:$A$152,Reference!$B$2:$B$152)} -> Nusa Tenggara Timur (NTT) | D2328: BPS-09031124 | E2328: 45352 | F2328: {=XLOOKUP(G2328,Reference!$F:$F,Reference!$D:$D,"null")} -> Makanan dan Pakaian | G2328: Makanan | H2328: 107.75 | I2328: 107.61 | J2328: =((H2328-I2328)/I2328)*100 -> 0.13009943 | K2328: =ifs(J2328=0,"Stabil",J2328<0,"Deflasi",J2328>0.51,"Inflasi Tinggi",TRUE,"Inflasi Normal") -> Inflasi Normal | L2328: =H2328-I2328 -> 0.14 | M2328: =IFS(AND(J2328>=0.5,L2328>=2),"Akselerasi Kuat",J2328>=0.5,"Akselerasi Persentase",L2328>=2,"Akselerasi Poin Absolut",TRUE,"Perubahan Normal") -> Perubahan Normal
A2329: TANJUNG PANDAN | B2329: =PROPER(A2329) -> Tanjung Pandan | C2329: {=xlookup(B2329,Reference!$A$2:$A$152,Reference!$B$2:$B$152)} -> Kepulauan Bangka Belitung | D2329: BPS-03532324 | E2329: 45352 | F2329: {=XLOOKUP(G2329,Reference!$F:$F,Reference!$D:$D,"null")} -> Rumah Tangga | G2329: Furniture | H2329: 100.31 | I2329: 100.31 | J2329: =((H2329-I2329)/I2329)*100 -> 0 | K2329: =ifs(J2329=0,"Stabil",J2329<0,"Deflasi",J2329>0.51,"Inflasi Tinggi",TRUE,"Inflasi Normal") -> Stabil | L2329: =H2329-I2329 -> 0 | M2329: =IFS(AND(J2329>=0.5,L2329>=2),"Akselerasi Kuat",J2329>=0.5,"Akselerasi Persentase",L2329>=2,"Akselerasi Poin Absolut",TRUE,"Perubahan Normal") -> Perubahan Normal
A2330: KAB DHARMASRAYA | B2330: =PROPER(A2330) -> Kab Dharmasraya | C2330: {=xlookup(B2330,Reference!$A$2:$A$152,Reference!$B$2:$B$152)} -> Sumatera Barat | D2330: BPS-01431124 | E2330: 45352 | F2330: {=XLOOKUP(G2330,Reference!$F:$F,Reference!$D:$D,"null")} -> Makanan dan Pakaian | G2330: Makanan | H2330: 117.88 | I2330: 115.09 | J2330: =((H2330-I2330)/I2330)*100 -> 2.4241898 | K2330: =ifs(J2330=0,"Stabil",J2330<0,"Deflasi",J2330>0.51,"Inflasi Tinggi",TRUE,"Inflasi Normal") -> Inflasi Tinggi | L2330: =H2330-I2330 -> 2.79 | M2330: =IFS(AND(J2330>=0.5,L2330>=2),"Akselerasi Kuat",J2330>=0.5,"Akselerasi Persentase",L2330>=2,"Akselerasi Poin Absolut",TRUE,"Perubahan Normal") -> Akselerasi Kuat
A2331: KOTA PARE PARE | B2331: =PROPER(A2331) -> Kota Pare Pare | C2331: {=xlookup(B2331,Reference!$A$2:$A$152,Reference!$B$2:$B$152)} -> Sulawesi Selatan | D2331: BPS-12731324 | E2331: 45352 | F2331: {=XLOOKUP(G2331,Reference!$F:$F,Reference!$D:$D,"null")} -> Makanan dan Pakaian | G2331: Pakaian | H2331: 103.19 | I2331: 103.19 | J2331: =((H2331-I2331)/I2331)*100 -> 0 | K2331: =ifs(J2331=0,"Stabil",J2331<0,"Deflasi",J2331>0.51,"Inflasi Tinggi",TRUE,"Inflasi Normal") -> Stabil | L2331: =H2331-I2331 -> 0 | M2331: =IFS(AND(J2331>=0.5,L2331>=2),"Akselerasi Kuat",J2331>=0.5,"Akselerasi Persentase",L2331>=2,"Akselerasi Poin Absolut",TRUE,"Perubahan Normal") -> Perubahan Normal
A2332: KAB TIMOR TENGAH SELATAN | B2332: =PROPER(A2332) -> Kab Timor Tengah Selatan | C2332: {=xlookup(B2332,Reference!$A$2:$A$152,Reference!$B$2:$B$152)} -> Nusa Tenggara Timur (NTT) | D2332: BPS-08821424 | E2332: 45323 | F2332: {=XLOOKUP(G2332,Reference!$F:$F,Reference!$D:$D,"null")} -> Makanan dan Pakaian | G2332: Alas Kaki | H2332: 104.07 | I2332: 104.07 | J2332: =((H2332-I2332)/I2332)*100 -> 0 | K2332: =ifs(J2332=0,"Stabil",J2332<0,"Deflasi",J2332>0.51,"Inflasi Tinggi",TRUE,"Inflasi Normal") -> Stabil | L2332: =H2332-I2332 -> 0 | M2332: =IFS(AND(J2332>=0.5,L2332>=2),"Akselerasi Kuat",J2332>=0.5,"Akselerasi Persentase",L2332>=2,"Akselerasi Poin Absolut",TRUE,"Perubahan Normal") -> Perubahan Normal
A2333: TEMBILAHAN | B2333: =PROPER(A2333) -> Tembilahan | C2333: {=xlookup(B2333,Reference!$A$2:$A$152,Reference!$B$2:$B$152)} -> Riau | D2333: BPS-01823124 | E2333: 45323 | F2333: {=XLOOKUP(G2333,Reference!$F:$F,Reference!$D:$D,"null")} -> Pendidikan dan Kesehatan | G2333: Pendidikan | H2333: 100.76 | I2333: 100.76 | J2333: =((H2333-I2333)/I2333)*100 -> 0 | K2333: =ifs(J2333=0,"Stabil",J2333<0,"Deflasi",J2333>0.51,"Inflasi Tinggi",TRUE,"Inflasi Normal") -> Stabil | L2333: =H2333-I2333 -> 0 | M2333: =IFS(AND(J2333>=0.5,L2333>=2),"Akselerasi Kuat",J2333>=0.5,"Akselerasi Persentase",L2333>=2,"Akselerasi Poin Absolut",TRUE,"Perubahan Normal") -> Perubahan Normal
A2334: KAB WAJO | B2334: =PROPER(A2334) -> Kab Wajo | C2334: {=xlookup(B2334,Reference!$A$2:$A$152,Reference!$B$2:$B$152)} -> Sulawesi Selatan | D2334: BPS-12333224 | E2334: 45352 | F2334: {=XLOOKUP(G2334,Reference!$F:$F,Reference!$D:$D,"null")} -> Pendidikan dan Kesehatan | G2334: Produk Kesehatan | H2334: 107.94 | I2334: 105.63 | J2334: =((H2334-I2334)/I2334)*100 -> 2.1868787 | K2334: =ifs(J2334=0,"Stabil",J2334<0,"Deflasi",J2334>0.51,"Inflasi Tinggi",TRUE,"Inflasi Normal") -> Inflasi Tinggi | L2334: =H2334-I2334 -> 2.31 | M2334: =IFS(AND(J2334>=0.5,L2334>=2),"Akselerasi Kuat",J2334>=0.5,"Akselerasi Persentase",L2334>=2,"Akselerasi Poin Absolut",TRUE,"Perubahan Normal") -> Akselerasi Kuat
A2335: KOTA JAKARTA | B2335: =PROPER(A2335) -> Kota Jakarta | C2335: {=xlookup(B2335,Reference!$A$2:$A$152,Reference!$B$2:$B$152)} -> DKI Jakarta | D2335: BPS-04231424 | E2335: 45352 | F2335: {=XLOOKUP(G2335,Reference!$F:$F,Reference!$D:$D,"null")} -> Makanan dan Pakaian | G2335: Alas Kaki | H2335: 96.15 | I2335: 96.3 | J2335: =((H2335-I2335)/I2335)*100 -> -0.15576324 | K2335: =ifs(J2335=0,"Stabil",J2335<0,"Deflasi",J2335>0.51,"Inflasi Tinggi",TRUE,"Inflasi Normal") -> Deflasi | L2335: =H2335-I2335 -> -0.15 | M2335: =IFS(AND(J2335>=0.5,L2335>=2),"Akselerasi Kuat",J2335>=0.5,"Akselerasi Persentase",L2335>=2,"Akselerasi Poin Absolut",TRUE,"Perubahan Normal") -> Perubahan Normal
... A2628: KAB KARIMUN | B2628: =PROPER(A2628) -> Kab Karimun | C2628: {=xlookup(B2628,Reference!$A$2:$A$152,Reference!$B$2:$B$152)} -> Kepulauan Riau | D2628: BPS-03931124 | E2628: 45352 | F2628: {=XLOOKUP(G2628,Reference!$F:$F,Reference!$D:$D,"null")} -> Makanan dan Pakaian | G2628: Makanan | H2628: 107.14 | I2628: 105.66 | J2628: =((H2628-I2628)/I2628)*100 -> 1.4007193 | K2628: =ifs(J2628=0,"Stabil",J2628<0,"Deflasi",J2628>0.51,"Inflasi Tinggi",TRUE,"Inflasi Normal") -> Inflasi Tinggi | L2628: =H2628-I2628 -> 1.48 | M2628: =IFS(AND(J2628>=0.5,L2628>=2),"Akselerasi Kuat",J2628>=0.5,"Akselerasi Persentase",L2628>=2,"Akselerasi Poin Absolut",TRUE,"Perubahan Normal") -> Akselerasi Persentase
A2629: KOTA BATAM | B2629: =PROPER(A2629) -> Kota Batam | C2629: {=XLOOKUP(B2629,Reference!$A$2:$A$152,Reference!$B$2:$B$152)} -> Kepulauan Riau | D2629: BPS-04031124 | E2629: 45352 | F2629: {=XLOOKUP(G2629,Reference!$F:$F,Reference!$D:$D,"null")} -> Makanan dan Pakaian | G2629: Makanan | H2629: 108.66 | I2629: 107.29 | J2629: =((H2629-I2629)/I2629)*100 -> 1.276913 | K2629: =ifs(J2629=0,"Stabil",J2629<0,"Deflasi",J2629>0.51,"Inflasi Tinggi",TRUE,"Inflasi Normal") -> Inflasi Tinggi | L2629: =H2629-I2629 -> 1.37 | M2629: =IFS(AND(J2629>=0.5,L2629>=2),"Akselerasi Kuat",J2629>=0.5,"Akselerasi Persentase",L2629>=2,"Akselerasi Poin Absolut",TRUE,"Perubahan Normal") -> Akselerasi Persentase
A2630: KOTA SEMARANG | B2630: =PROPER(A2630) -> Kota Semarang | C2630: {=XLOOKUP(B2630,Reference!$A$2:$A$152,Reference!$B$2:$B$152)} -> Jawa Tengah | D2630: BPS-06032124 | E2630: 45352 | F2630: {=XLOOKUP(G2630,Reference!$F:$F,Reference!$D:$D,"null")} -> Rumah Tangga | G2630: Sewa Rumah | H2630: 100.82 | I2630: 100.82 | J2630: =((H2630-I2630)/I2630)*100 -> 0 | K2630: =ifs(J2630=0,"Stabil",J2630<0,"Deflasi",J2630>0.51,"Inflasi Tinggi",TRUE,"Inflasi Normal") -> Stabil | L2630: =H2630-I2630 -> 0 | M2630: =IFS(AND(J2630>=0.5,L2630>=2),"Akselerasi Kuat",J2630>=0.5,"Akselerasi Persentase",L2630>=2,"Akselerasi Poin Absolut",TRUE,"Perubahan Normal") -> Perubahan Normal
A2631: KAB ACEH TAMIANG | B2631: =PROPER(A2631) -> Kab Aceh Tamiang | C2631: {=XLOOKUP(B2631,Reference!$A$2:$A$152,Reference!$B$2:$B$152)} -> Aceh | D2631: BPS-00322224 | E2631: 45323 | F2631: {=XLOOKUP(G2631,Reference!$F:$F,Reference!$D:$D,"null")} -> Rumah Tangga | G2631: Listrik | H2631: 99.84 | I2631: 99.84 | J2631: =((H2631-I2631)/I2631)*100 -> 0 | K2631: =ifs(J2631=0,"Stabil",J2631<0,"Deflasi",J2631>0.51,"Inflasi Tinggi",TRUE,"Inflasi Normal") -> Stabil | L2631: =H2631-I2631 -> 0 | M2631: =IFS(AND(J2631>=0.5,L2631>=2),"Akselerasi Kuat",J2631>=0.5,"Akselerasi Persentase",L2631>=2,"Akselerasi Poin Absolut",TRUE,"Perubahan Normal") -> Perubahan Normal
A2632: KAB KAYONG UTARA | B2632: =PROPER(A2632) -> Kab Kayong Utara | C2632: {=XLOOKUP(B2632,Reference!$A$2:$A$152,Reference!$B$2:$B$152)} -> Kalimantan Barat | D2632: BPS-09423224 | E2632: 45323 | F2632: {=XLOOKUP(G2632,Reference!$F:$F,Reference!$D:$D,"null")} -> Pendidikan dan Kesehatan | G2632: Produk Kesehatan | H2632: 105.84 | I2632: 105.82 | J2632: =((H2632-I2632)/I2632)*100 -> 0.018900019 | K2632: =ifs(J2632=0,"Stabil",J2632<0,"Deflasi",J2632>0.51,"Inflasi Tinggi",TRUE,"Inflasi Normal") -> Inflasi Normal | L2632: =H2632-I2632 -> 0.02 | M2632: =IFS(AND(J2632>=0.5,L2632>=2),"Akselerasi Kuat",J2632>=0.5,"Akselerasi Persentase",L2632>=2,"Akselerasi Poin Absolut",TRUE,"Perubahan Normal") -> Perubahan Normal
A2633: KAB MUKO MUKO | B2633: =PROPER(A2633) -> Kab Muko Muko | C2633: {=XLOOKUP(B2633,Reference!$A$2:$A$152,Reference!$B$2:$B$152)} -> Bengkulu | D2633: BPS-02922324 | E2633: 45323 | F2633: {=XLOOKUP(G2633,Reference!$F:$F,Reference!$D:$D,"null")} -> Rumah Tangga | G2633: Furniture | H2633: 122.67 | I2633: 122.67 | J2633: =((H2633-I2633)/I2633)*100 -> 0 | K2633: =ifs(J2633=0,"Stabil",J2633<0,"Deflasi",J2633>0.51,"Inflasi Tinggi",TRUE,"Inflasi Normal") -> Stabil | L2633: =H2633-I2633 -> 0 | M2633: =IFS(AND(J2633>=0.5,L2633>=2),"Akselerasi Kuat",J2633>=0.5,"Akselerasi Persentase",L2633>=2,"Akselerasi Poin Absolut",TRUE,"Perubahan Normal") -> Perubahan Normal
A2634: KOTA MADIUN | B2634: =PROPER(A2634) -> Kota Madiun | C2634: {=XLOOKUP(B2634,Reference!$A$2:$A$152,Reference!$B$2:$B$152)} -> Jawa Timur | D2634: BPS-07331424 | E2634: 45352 | F2634: {=XLOOKUP(G2634,Reference!$F:$F,Reference!$D:$D,"null")} -> Makanan dan Pakaian | G2634: Alas Kaki | H2634: 101.58 | I2634: 101.58 | J2634: =((H2634-I2634)/I2634)*100 -> 0 | K2634: =ifs(J2634=0,"Stabil",J2634<0,"Deflasi",J2634>0.51,"Inflasi Tinggi",TRUE,"Inflasi Normal") -> Stabil | L2634: =H2634-I2634 -> 0 | M2634: =IFS(AND(J2634>=0.5,L2634>=2),"Akselerasi Kuat",J2634>=0.5,"Akselerasi Persentase",L2634>=2,"Akselerasi Poin Absolut",TRUE,"Perubahan Normal") -> Perubahan Normal
A2635: KOTA SEMARANG | B2635: =PROPER(A2635) -> Kota Semarang | C2635: {=XLOOKUP(B2635,Reference!$A$2:$A$152,Reference!$B$2:$B$152)} -> Jawa Tengah | D2635: BPS-06031224 | E2635: 45352 | F2635: {=XLOOKUP(G2635,Reference!$F:$F,Reference!$D:$D,"null")} -> Makanan dan Pakaian | G2635: Minuman | H2635: 105.87 | I2635: 105.86 | J2635: =((H2635-I2635)/I2635)*100 -> 0.0094464387 | K2635: =ifs(J2635=0,"Stabil",J2635<0,"Deflasi",J2635>0.51,"Inflasi Tinggi",TRUE,"Inflasi Normal") -> Inflasi Normal | L2635: =H2635-I2635 -> 0.01 | M2635: =IFS(AND(J2635>=0.5,L2635>=2),"Akselerasi Kuat",J2635>=0.5,"Akselerasi Persentase",L2635>=2,"Akselerasi Poin Absolut",TRUE,"Perubahan Normal") -> Perubahan Normal
A2636: KAB KAPUAS | B2636: =PROPER(A2636) -> Kab Kapuas | C2636: {=XLOOKUP(B2636,Reference!$A$2:$A$152,Reference!$B$2:$B$152)} -> Kalimantan Tengah | D2636: BPS-09831324 | E2636: 45352 | F2636: {=XLOOKUP(G2636,Reference!$F:$F,Reference!$D:$D,"null")} -> Makanan dan Pakaian | G2636: Pakaian | H2636: 105.15 | I2636: 105.11 | J2636: =((H2636-I2636)/I2636)*100 -> 0.038055371 | K2636: =ifs(J2636=0,"Stabil",J2636<0,"Deflasi",J2636>0.51,"Inflasi Tinggi",TRUE,"Inflasi Normal") -> Inflasi Normal | L2636: =H2636-I2636 -> 0.04 | M2636: =IFS(AND(J2636>=0.5,L2636>=2),"Akselerasi Kuat",J2636>=0.5,"Akselerasi Persentase",L2636>=2,"Akselerasi Poin Absolut",TRUE,"Perubahan Normal") -> Perubahan Normal
A2637: KAB MUARA ENIM | B2637: =PROPER(A2637) -> Kab Muara Enim | C2637: {=XLOOKUP(B2637,Reference!$A$2:$A$152,Reference!$B$2:$B$152)} -> Sumatera Selatan | D2637: BPS-02633124 | E2637: 45352 | F2637: {=XLOOKUP(G2637,Reference!$F:$F,Reference!$D:$D,"null")} -> Pendidikan dan Kesehatan | G2637: Pendidikan | H2637: 100 | I2637: 100 | J2637: =((H2637-I2637)/I2637)*100 -> 0 | K2637: =ifs(J2637=0,"Stabil",J2637<0,"Deflasi",J2637>0.51,"Inflasi Tinggi",TRUE,"Inflasi Normal") -> Stabil | L2637: =H2637-I2637 -> 0 | M2637: =IFS(AND(J2637>=0.5,L2637>=2),"Akselerasi Kuat",J2637>=0.5,"Akselerasi Persentase",L2637>=2,"Akselerasi Poin Absolut",TRUE,"Perubahan Normal") -> Perubahan Normal
A2638: KOTA MAKASSAR | B2638: =PROPER(A2638) -> Kota Makassar | C2638: {=XLOOKUP(B2638,Reference!$A$2:$A$152,Reference!$B$2:$B$152)} -> Sulawesi Selatan | D2638: BPS-12621224 | E2638: 45323 | F2638: {=XLOOKUP(G2638,Reference!$F:$F,Reference!$D:$D,"null")} -> Makanan dan Pakaian | G2638: Minuman | H2638: 105.5 | I2638: 105.52 | J2638: =((H2638-I2638)/I2638)*100 -> -0.018953753 | K2638: =ifs(J2638=0,"Stabil",J2638<0,"Deflasi",J2638>0.51,"Inflasi Tinggi",TRUE,"Inflasi Normal") -> Deflasi | L2638: =H2638-I2638 -> -0.02 | M2638: =IFS(AND(J2638>=0.5,L2638>=2),"Akselerasi Kuat",J2638>=0.5,"Akselerasi Persentase",L2638>=2,"Akselerasi Poin Absolut",TRUE,"Perubahan Normal") -> Perubahan Normal
A2639: KOTA PALOPO | B2639: =PROPER(A2639) -> Kota Palopo | C2639: {=XLOOKUP(B2639,Reference!$A$2:$A$152,Reference!$B$2:$B$152)} -> Sulawesi Selatan | D2639: BPS-12822224 | E2639: 45323 | F2639: {=XLOOKUP(G2639,Reference!$F:$F,Reference!$D:$D,"null")} -> Rumah Tangga | G2639: Listrik | H2639: 100.05 | I2639: 100.05 | J2639: =((H2639-I2639)/I2639)*100 -> 0 | K2639: =ifs(J2639=0,"Stabil",J2639<0,"Deflasi",J2639>0.51,"Inflasi Tinggi",TRUE,"Inflasi Normal") -> Stabil | L2639: =H2639-I2639 -> 0 | M2639: =IFS(AND(J2639>=0.5,L2639>=2),"Akselerasi Kuat",J2639>=0.5,"Akselerasi Persentase",L2639>=2,"Akselerasi Poin Absolut",TRUE,"Perubahan Normal") -> Perubahan Normal
...

Sheet Business Question
B2: Business Question A
B3: Pertanyaan | C3: Jawaban
B4: 1. Top 3 Kota/Kabupaten dengan Laju Inflasi M-t-M tertinggi pada bulan Maret 2024? | C4: Top 3 Kota/Kabupaten dengan Laju Inflasi M-t-M pada bulan Maret ialah: Kota Tangerang, Kota Denpasar, Kab Lampung Timur
B5: 2. Kota/Kabupaten mana yang memiliki rata-rata Perubahan Poin IHK tertinggi pada bulan Maret 2024? | C5: Kota dengan rata-rata Perubahan Poin IHK tertinggi pada Maret 2024 ialah Kab Lampung Timur,
B6: 3. Kota/Kabupaten yang mengalami Deflasi paling dalam untuk tiap kategori pada Februari 2024? | C6: Kota/Kabupaten dengan Deflasi paling dalam pada tiap kategori periode Februari 2024 ialah sebagai berikut: 1. Kategori Alas Kaki (Kab Hulu Sungai Tengah; 2. Kategori Furniture (Kab Karo); 3. Kategori Kendaraan (Kab Karo); 4. Kategori Listrik (Kab Karo); 5. Kategori Makanan (Kab Maluku Tengah); 6. Kategori Minuman (Kab Toli Toli); 7. Kategori Pakaian (Kab Muara Enim); 8. Kategori Pendidikan (Kab Nabire); 9. Kategori Produk Kesehatan (Mamuju); 10. Kategori Rekreasi (Kab Maluku Tengah)
B7: 4. Indikasi cepat, berapa rata-rata Laju Inflasi (M-t-M) untuk kategori Minuman di seluruh provinsi pada bulan Februari 2024? | C7: Berdasarkan analisis, rata-rata Laju Inflasi ( M-t-M) untuk kategori Minuman pada bulan februari pada seluruh provinsi ialah sebesar 0,102
B8: 5. Berapa persentase data yang memiliki status Inflasi Normal dibandingkan seluruh data? | C8: Terdapat 21,58% status Inflasi Normal dari keseluruhan data yang ada
B9: 6. Kategori apa yang mengalami perubahan Laju Inflasi (M-t-M) antar bulan terbesar, antara Februari dan Maret 2024? | C9: Kategori dengan perubahan Laju Inflasi (M-t-M) terbesar dari bulan februari ke Maret ialah kategori Makanan, dimana pada bulan februari laju inflasi (M-t-M)-nya berada pada 0,78 sedangkan pada bulan Maret, laju inflasi (M-t-M)-nya berada pada 1,45. Dengan kata lain memiliki selisih 0,67 yang merupakan yang terbesar di antara kategori lainnya.
B10: 7. Indikasi cepat, apakah rata-rata Laju Inflasi (M-t-M) di Kota Jakarta lebih tinggi dibandingkan Kota Surabaya pada bulan Maret 2024?, Berapa selisihnya? | C10: Berdasarkan analisis, Kota Jakarta memiliki rata-rata Laju Inflasi (M-t-M) lebih rendah dari Surabaya, dimana nilai rata-rata Laju Inflasi (M-t-M) jakarta sebesar 0,21. Sedangkan Surabaya memiliki rata-rata Laju Inflasi (M-t-M) sebesar 0,37. Terdapat selisih 0,16 diantara keduanya.
B11: 8. Provinsi mana yang paling sering mengalami Perubahan Normal pada bulan Februari 2024? | C11: Provinsi Jawa timur merupakan provinsi dengan frekuensi Perubahan Normal paling sering dengan jumlah perubahan Normal sebanyak 104 dengan persentase 7,17%
B14: Business Question B
B15: 1. Data Agregat a. Jumlah Kota/Kabupaten b. Jumlah Provinsi c. Rata-rata Laju Inflasi M-t-M
B16: 2. Tren Inflasi Nasional yang menampilkan rata-rata Laju Inflasi M-t-M Nasional dari Februari hingga Maret.
B17: 3. Peta Panas Regional yang menunjukkan Nama Provinsi rata-rata Laju Inflasi M-t-M.
B18: 4. Distribusi Peringatan Inflasi yang menampilkan persentase Kota/Kabupaten yang termasuk dalam Akselerasi Kuat vs. Akselerasi Persentase pada bulan terakhir.
B19: 5. Perbandingan Sektor yang membandingkan rata-rata IHK Bulan Ini dan rata-rata IHK Bulan Lalu untuk 3 Tipe Sektor Ekonomi teratas.
B20: 6. Hitungan Deflasi yang menampilkan jumlah Kota/Kabupaten yang mengalami Deflasi (gunakan Filter Kriteria Inflasi).
B21: 7. Top 5 Kontributor Poin yang menunjukkan 5 Nama Kota/Kabupaten dengan rata-rata Perubahan Poin IHK M-t-M tertinggi.
B22: 8. Kontrol Interaktif berdasarkan Nama Provinsi dan Kelompok Kategori

Sheet Pivot Table
A1: 1. Top 3 Kota/Kabupaten dengan Laju Inflasi M-t-M tertinggi pada bulan Maret 2024? | D1: 2. Kota/Kabupaten mana yang memiliki rata-rata Perubahan Poin IHK tertinggi pada bulan Maret 2024? | G1: 3. Kota/Kabupaten yang mengalami Deflasi paling dalam untuk tiap kategori pada Februari 2024? | K1: 4. Indikasi cepat, berapa rata-rata Laju Inflasi (M-t-M) untuk kategori Minuman di seluruh provinsi pada bulan Februari 2024? | O1: 5. Berapa persentase data yang memiliki status Inflasi Normal dibandingkan seluruh data? | R1: 6. Kategori apa yang mengalami perubahan Laju Inflasi (M-t-M) antar bulan terbesar, antara Februari dan Maret 2024? | W1: 7. Indikasi cepat, apakah rata-rata Laju Inflasi (M-t-M) di Kota Jakarta lebih tinggi dibandingkan Kota Surabaya pada bulan Maret 2024?, Berapa selisihnya? | AB1: 8. Provinsi mana yang paling sering mengalami Perubahan Normal pada bulan Februari 2024?
U3: Fluktuasi | Z3: Selisih
U4: =T4-S4 -> 0.66624588 | Z4: =X4-Y4 -> 0.15609091
U5: =T5-S5 -> 0.10956476
U6: =T6-S6 -> 0.18585682
U7: =T7-S7 -> 0.069243468
U8: =T8-S8 -> 0.093179667
U9: =T9-S9 -> 0.037043986
U10: =T10-S10 -> 0.19515351
U11: =T11-S11 -> 0.11091658
U12: =T12-S12 -> 0.034646586
U13: =T13-S13 -> 0.007304537
U14: =T14-S14 -> 0.066692768

Sheet Pivot Table 5
